{"errorMessage": "'Description'", "errorType": "KeyError", "requestId": "7fa4d50d-b932-4c42-8f2c-6c332aef6ca5", "stackTrace": ["  File \"/var/task/app.py\", line 206, in lambda_handler\n    df[\"Puntaje Descripci\u00f3n\"] = df[\"Description\"].apply(evaluar_descripcion)\n", "  File \"/var/task/pandas/core/frame.py\", line 4107, in __getitem__\n    indexer = self.columns.get_loc(key)\n", "  File \"/var/task/pandas/core/indexes/range.py\", line 417, in get_loc\n    raise KeyError(key)\n"]}